Workbook

Sheet BOM
A1: Subsystem | B1: Component | C1: Exact part / spec | D1: Qty | E1: Unit cost (INR) | F1: Line total (INR, formula) | G1: Est. (INR) - ESTIMATE range | H1: Vendor | I1: Vendor city | J1: Sourcing flag | K1: Lead time (days) | L1: Product URL | M1: Alt vendor | N1: Notes | O1: Price evidence | P1: Checked on | Q1: Est. low (INR) | R1: Est. high (INR)
A2: Edge Node | B2: Raspberry Pi 5 8GB | C2: Raspberry Pi 5 Model B, BCM2712, 8GB LPDDR4X | D2: 1 | E2: 22499 | F2: =IF(ISNUMBER(E2),D2*E2,0) -> 22499 | H2: Probots (Probots Technologies) | I2: Bengaluru (Nagarbhavi; contact page) | J2: Domestic | K2: 4 | L2: https://probots.co.in/raspberry-pi-5-model-b-bcm2712-arm-cortex-a76-8gb-ram-2-4ghz-single-board-computer.html | M2: Robocraze, Bengaluru: Rs 19,999 incl GST (SOLD OUT 24-Oct) https://robocraze.com/products/raspberry-pi-5-8gb ; element14 India Rs 16,717.93 (GST n/s, ships from SG/UK stock, 3-6 business days - IMPORTED shipment) | N2: Listed Rs 22,499.00 incl GST. In stock. Approved-reseller status of Probots not verified. Hubtronics (Rs 20,765) rejected: Pune. | O2: Product page | P2: 2026-10-25 | Q2: 0 | R2: 0
A3: Edge Node | B3: Raspberry Pi AI HAT+ 26 TOPS | C3: Raspberry Pi AI HAT+ (Hailo-8, 26 TOPS), PCIe Gen3 x1 | D3: 1 | E3: 14999 | F3: =IF(ISNUMBER(E3),D3*E3,0) -> 14999 | H3: Probots (Probots Technologies) | I3: Bengaluru (Nagarbhavi; contact page) | J3: Domestic | K3: 4 | L3: https://probots.co.in/official-raspberry-pi-ai-hat-26-tops.html | M3: Robocraze, Bengaluru: Rs 11,309 incl GST (SOLD OUT 24-Oct) https://robocraze.com/products/official-raspberry-pi-ai-hat-26-tops | N3: Listed Rs 14,999.00 incl GST. In stock. Hubtronics (Rs 10,989, OOS) rejected: Pune. Uses the Pi 5's only PCIe lane, so boot media is microSD (no NVMe). | O3: Product page | P3: 2026-10-25 | Q3: 0 | R3: 0
A4: Edge Node | B4: Active cooler | C4: Official Raspberry Pi 5 Active Cooler (heatsink + PWM fan) | D4: 1 | E4: 749 | F4: =IF(ISNUMBER(E4),D4*E4,0) -> 749 | H4: Probots (Probots Technologies) | I4: Bengaluru (Nagarbhavi; contact page) | J4: Domestic | K4: 4 | L4: https://probots.co.in/official-raspberry-pi-5-active-cooler-heatsink-fan.html | M4: No 2nd allowed-city vendor verified (Hubtronics Rs 560 is Pune) | N4: Listed Rs 749.00 incl GST. In stock. Design note (25 Oct): sits inside the sealed box and circulates the internal air; it does not remove heat from the box (CALCS section 5). | O4: Product page | P4: 2026-10-25 | Q4: 0 | R4: 0
A5: Edge Node | B5: microSD card 128GB | C5: SanDisk 128GB microSDXC (A1/A2 class to confirm at checkout) | D5: 1 | E5: 2725 | F5: =IF(ISNUMBER(E5),D5*E5,0) -> 2725 | H5: Robocraze (TIF Labs Pvt Ltd) | I5: Bengaluru (Kalyan Nagar warehouse; contact page) | J5: Domestic | K5: 4 | L5: https://robocraze.com/search?q=sandisk | M5: Robocraze SanDisk Extreme 128GB A2 Rs 3,643 (sold out) | N5: Listed Rs 2,725.00 incl GST. Shown as add-to-cart on search page; >=64GB requirement met. | O5: Store/category listing page | P5: 2026-10-24 | Q5: 0 | R5: 0
A6: Edge Node | B6: USB-C PSU (bench / commissioning) | C6: Raspberry Pi 27W USB-C PSU 5.1V 5A, white, IN plug | D6: 1 | E6: 1749 | F6: =IF(ISNUMBER(E6),D6*E6,0) -> 1749 | H6: Probots (Probots Technologies) | I6: Bengaluru (Nagarbhavi; contact page) | J6: Domestic | K6: 4 | L6: https://probots.co.in/raspberry-pi-27w-usb-c-power-supply-white-in-plug.html | M6: Robocraze: Rs 1,254 (white) on search page, stock not shown | N6: Listed Rs 1,749.00 incl GST. In stock. Bench use; in the enclosure the Pi is fed by the 24V->5V buck below. | O6: Product page | P6: 2026-10-25 | Q6: 0 | R6: 0
A7: Edge Node | B7: 24V->5.1V 5A buck (Pi 5 feed in enclosure) | C7: XL4015 step-down, 4-38V in, 1.25-36V out, 5A max | D7: 1 | E7: 299 | F7: =IF(ISNUMBER(E7),D7*E7,0) -> 299 | H7: Probots (Probots Technologies) | I7: Bengaluru (Nagarbhavi; contact page) | J7: Domestic | K7: 4 | L7: https://probots.co.in/xl4015-step-down-buck-converter-adjustable-max-output-36v-5a.html | M7: Thingbits / Robocraze equivalents (not priced) | N7: Listed Rs 299.00 incl GST. In stock. 5A is the module's max: derate and add heatsink, target to be bench-verified. A Mean Well DC-DC 5V module would be the industrial option (quote). | O7: Product page | P7: 2026-10-25 | Q7: 0 | R7: 0
A8: Edge Node | B8: Pi 5 UPS module (>=10 min ride-through) | C8: Geekworm X1202 UPS HAT for Raspberry Pi 5 (18650 based, 5.1 V 5 A output) | D8: 1 | E8: quote needed | F8: =IF(ISNUMBER(E8),D8*E8,0) -> 0 | G8: 4,599-4,599 (line) | H8: Probots (Probots Technologies) | I8: Bengaluru (Nagarbhavi; contact page) | J8: Domestic | K8: 4 | L8: https://probots.co.in/metal-case-raspberry-pi-5-x1202-ups-board.html | M8: Geekworm X1202 (Robu.in - Pune, rejected); quote from Robocraze/Thingbits | N8: 25-Oct: the 24-Oct figure of Rs 4,599 came from a related-products block and was labelled 'Waveshare'. The Probots page checked on 25-Oct is the Geekworm X1202-C1 metal case at Rs 2,649 incl GST (in stock); it does not show a Rs 4,599 UPS board. Rs 4,599 is kept only as the budget placeholder until a quote or the board's own product page is seen. Geekworm sells the X1202 as a 4-cell board; Probots says 2 cells. UPS covers the Pi only (not the PoE switch or camera). Ride-through time is a target, to be bench-verified. Limitation (25 Oct): the PoE switch and camera have no UPS, so ANPR is lost on a mains outage while the Pi and RFID reader keep running (docs/OPEN_DECISIONS.md D3). | O8: ESTIMATE - quote needed | P8: 2026-10-25 | Q8: 4599 | R8: 4599
A9: Edge Node | B9: 18650 Li-ion cells for UPS module | C9: Protected 18650, 2500-3000 mAh (2 per Probots X1202 page; Geekworm describes a 4-cell board: confirm count) | D9: 2 | E9: quote needed | F9: =IF(ISNUMBER(E9),D9*E9,0) -> 0 | G9: 500-900 (line) | H9: Probots (Probots Technologies) | I9: Bengaluru (Nagarbhavi; contact page) | J9: Domestic | K9: 7 | M9: Thingbits, Mumbai | N9: Not priced: quote needed. | O9: ESTIMATE - quote needed | P9: 2026-10-24 | Q9: 500 | R9: 900
A10: Edge Node | B10: SUBTOTAL - Edge Node | F10: =SUM(F2:F9) -> 43020 | K10: =MAX(K2:K9) -> 7 | Q10: =SUM(Q2:Q9) -> 5099 | R10: =SUM(R2:R9) -> 5499
A12: Lane Controller PCB | B12: MCU module | C12: Espressif ESP32-S3-WROOM-1-N16R8 (16MB flash, 8MB PSRAM) | D12: 2 | E12: 1010.63 | F12: =IF(ISNUMBER(E12),D12*E12,0) -> 2021.26 | H12: LionCircuits | I12: Bengaluru (080 phone; Karnataka facility) - address not on site, confirm | J12: Domestic | K12: 10 | L12: https://lioncircuits.com/parts/ESP32-S3-WROOM-1-N16R8 | M12: Probots ESP32-S3 N16R8 dev board Rs 1,299 incl GST (bench firmware) https://probots.co.in/esp32-s3-wroom-1-n16r8-development-board-wireless-module-wifi-bluetooth.html | N12: Listed Rs 856.47; GST not stated, +18% applied (conservative). Qty 1 + 1 spare. Ships in 7-10 days (stated). Page text says '6MB Quad SPI', confirm flash size. | O12: Product page | P12: 2026-10-25 | Q12: 0 | R12: 0
A13: Lane Controller PCB | B13: RS485 transceiver | C13: Maxim MAX3485ESA+T, 3.3V, SOIC-8, 10 Mbps | D13: 0 | E13: 1100.09 | F13: =IF(ISNUMBER(E13),D13*E13,0) -> 0 | H13: LionCircuits | I13: Bengaluru (080 phone; Karnataka facility) - address not on site, confirm | J13: Domestic | K13: 10 | L13: https://lioncircuits.com/parts/MAX3485ESA+T | M13: Probots UART TTL-RS485 auto-flow module PRO2056 Rs 399 incl GST https://probots.co.in/uart-ttl-to-rs485-serial-converter.html | N13: SUPERSEDED 25 Oct: the schematic uses TI THVD1450DR (see the line 'Schematic parts not otherwise listed'). Qty set to 0; the priced MAX3485ESA is kept visible for reference only. Original note: Listed Rs 932.28; GST not stated, +18% applied (conservative). Qty 1 + 1 spare. Ships in 7-10 days (stated). | O13: Product page | P13: 2026-10-24 | Q13: 0 | R13: 0
A14: Lane Controller PCB | B14: RS485 TVS | C14: Semtech SM712.TCT, asymmetric 12V/7V TVS, SOT-23, 400W | D14: 2 | E14: 196.53 | F14: =IF(ISNUMBER(E14),D14*E14,0) -> 393.06 | H14: LionCircuits | I14: Bengaluru (080 phone; Karnataka facility) - address not on site, confirm | J14: Domestic | K14: 10 | L14: https://lioncircuits.com/parts/SM712.TCT | N14: Listed Rs 166.55; GST not stated, +18% applied (conservative). Ships in 7-10 days (stated). | O14: Product page | P14: 2026-10-24 | Q14: 0 | R14: 0
A15: Lane Controller PCB | B15: H-bridge motor driver | C15: BTS7960 43A dual half-bridge module (IBT-2) | D15: 1 | E15: 699 | F15: =IF(ISNUMBER(E15),D15*E15,0) -> 699 | H15: Probots (Probots Technologies) | I15: Bengaluru (Nagarbhavi; contact page) | J15: Domestic | K15: 4 | L15: https://probots.co.in/bts7960-43a-stepper-motor-driver-h-bridge-high-power-module-motor-control.html | M15: Thingbits, Mumbai: Rs 251.34 incl GST (SOLD OUT) https://www.thingbits.in/products/bts7960-43a-h-bridge-motor-driver | N15: Listed Rs 699.00 incl GST. In stock. ONE DESIGN (25 Oct): the schematic now uses this IBT-2 module (2x BTS7960, 5.5-27 V motor supply, so 24 V is inside its range; the former BTN8982TA pair is gone). Only its 8 logic pins reach the PCB (header J14); the module's B+/B-/M+/M- terminals are wired directly: contactor K1 contacts -> B+/B-, motor -> M+/M-. Add 470 uF 50 V + SMCJ28A across B+/B- at the module (in the misc line). Logic is 5 V (on-board buffer); the PCB level-shifts with 74AHCT1G08. Module IS pins have a 1k to GND each. Thingbits Mumbai Rs 251.34 was sold out. | O15: Product page | P15: 2026-10-25 | Q15: 0 | R15: 0
A16: Lane Controller PCB | B16: 24V->5V buck (logic rail) | C16: XL4015 step-down, 5A max | D16: 0 | E16: 299 | F16: =IF(ISNUMBER(E16),D16*E16,0) -> 0 | H16: Probots (Probots Technologies) | I16: Bengaluru (Nagarbhavi; contact page) | J16: Domestic | K16: 4 | L16: https://probots.co.in/xl4015-step-down-buck-converter-adjustable-max-output-36v-5a.html | N16: SUPERSEDED 25 Oct: the schematic uses a TPS54560BDDA 5 A buck on the PCB (parts in the line 'Schematic parts not otherwise listed'). Qty set to 0. The XL4015 modules on the P10 and Edge lines are separate. Original note: Listed Rs 299.00 incl GST. In stock. | O16: Product page | P16: 2026-10-25 | Q16: 0 | R16: 0
A17: Lane Controller PCB | B17: 3.3V regulator | C17: Diodes AP2112K-3.3TRG1 LDO 600mA SOT-23-5 | D17: 0 | E17: 21.33 | F17: =IF(ISNUMBER(E17),D17*E17,0) -> 0 | H17: LionCircuits | I17: Bengaluru (080 phone; Karnataka facility) - address not on site, confirm | J17: Domestic | K17: 10 | L17: https://lioncircuits.com/parts/AP2112K-3.3TRG1 | N17: SUPERSEDED 25 Oct: the schematic uses a TLV62569DBVR 2 A buck (the 600 mA LDO was marginal for ESP32-S3 Wi-Fi peaks). Qty set to 0. Original note: Listed Rs 18.08; GST not stated, +18% applied (conservative). Lowest tier is 10 pcs. 600mA is tight for ESP32-S3 Wi-Fi peaks: bench-verify, or switch to a 1A LDO. | O17: Product page | P17: 2026-10-24 | Q17: 0 | R17: 0
A18: Lane Controller PCB | B18: Optocouplers | C18: PC817C 4-SMD (limit switches, photo-beam, E-stop sense) | D18: 10 | E18: 4.24 | F18: =IF(ISNUMBER(E18),D18*E18,0) -> 42.4 | H18: LionCircuits | I18: Bengaluru (080 phone; Karnataka facility) - address not on site, confirm | J18: Domestic | K18: 10 | L18: https://lioncircuits.com/parts/PC817C | N18: Listed Rs 3.59; GST not stated, +18% applied (conservative). | O18: Product page | P18: 2026-10-24 | Q18: 0 | R18: 0
A19: Lane Controller PCB | B19: Screw terminals | C19: 2-pin fixed screw terminal block, 5.08mm pitch | D19: 12 | E19: 15 | F19: =IF(ISNUMBER(E19),D19*E19,0) -> 180 | H19: Probots (Probots Technologies) | I19: Bengaluru (Nagarbhavi; contact page) | J19: Domestic | K19: 4 | L19: https://probots.co.in/2-pin-fixed-screw-terminal-block-connector-5-08mm.html | N19: Listed Rs 15.00 incl GST. In stock. | O19: Product page | P19: 2026-10-24 | Q19: 0 | R19: 0
A20: Lane Controller PCB | B20: Buzzer | C20: Piezo buzzer B-27, 3-24V continuous | D20: 1 | E20: 49 | F20: =IF(ISNUMBER(E20),D20*E20,0) -> 49 | H20: Probots (Probots Technologies) | I20: Bengaluru (Nagarbhavi; contact page) | J20: Domestic | K20: 4 | L20: https://probots.co.in/piezo-electric-buzzer-alarm-3v-24v-continuous-b27.html | N20: Listed Rs 49.00 incl GST. Price seen on Probots listing grid. | O20: Store/category listing page | P20: 2026-10-24 | Q20: 0 | R20: 0
A21: Lane Controller PCB | B21: Status RGB LED | C21: WS2812 12-LED ring board | D21: 1 | E21: 149 | F21: =IF(ISNUMBER(E21),D21*E21,0) -> 149 | H21: Probots (Probots Technologies) | I21: Bengaluru (Nagarbhavi; contact page) | J21: Domestic | K21: 4 | L21: https://probots.co.in/rgb-led-12-bit-ws2812-circular-development-board.html | N21: Listed Rs 149.00 incl GST. In stock. | O21: Product page | P21: 2026-10-24 | Q21: 0 | R21: 0
A22: Lane Controller PCB | B22: PCB fabrication | C22: 2-layer FR4 ~100x80 mm, 5 pcs (1 lot) | D22: 1 | E22: 942.82 | F22: =IF(ISNUMBER(E22),D22*E22,0) -> 942.82 | H22: LionCircuits | I22: Bengaluru (080 phone; Karnataka facility) - address not on site, confirm | J22: Domestic | K22: 9 | L22: https://lioncircuits.com/ | M22: Quote also from another Bengaluru/Delhi fab | N22: Listed Rs 799.00; GST not stated, +18% applied (conservative). Advertised '5 boards for Rs 799 in 5-6 days'. Final price depends on size/spec quote. Lead time = 5-6 days + about 3 days shipping. | O22: Vendor homepage offer | P22: 2026-10-24 | Q22: 0 | R22: 0
A23: Lane Controller PCB | B23: Misc passives & connectors | C23: R/C 0805, electrolytics, ferrites, SMBJ33A on 24V, headers, JST, RJ45/RS485 connector, polyfuse | D23: 1 | E23: quote needed | F23: =IF(ISNUMBER(E23),D23*E23,0) -> 0 | G23: 800-1,500 (line) | H23: LionCircuits | I23: Bengaluru (080 phone; Karnataka facility) - address not on site, confirm | J23: Domestic | K23: 10 | L23: https://lioncircuits.com/ | M23: Probots | N23: Quote needed. One lot. Now also covers: 470 uF 50 V low-ESR + SMCJ28A at the IBT-2 module terminals, 1x8 2.54 mm header for J14, 2x SM712-class TVS spares, ferrites, JST-XH, RJ45/Cat6 (see spec). Range unchanged from 24 Oct: re-quote. | O23: ESTIMATE - quote needed | P23: 2026-10-24 | Q23: 800 | R23: 1500
A24: Lane Controller PCB | B24: Schematic parts not otherwise listed | C24: TI THVD1450DR RS485 (replaces MAX3485ESA); TPS54560BDDA 5 A buck + 6.8 uH inductor + B560C + FQD11P06 reverse-polarity FET (replaces XL4015 on the PCB); TLV62569DBVR 3.3 V buck + 2.2 uH (replaces AP2112K); TPS3823-33DBVR watchdog; 3x 74AHCT1G08 (U9, U10, U19); SN74HCT245PWR; USBLC6-2SC6; GCT USB4105 USB-C; 2x 2N7002; 2x IRLML0060; BAT54/SS14/S1M/1N4148W diodes; 3 A nano fuse + MF-R075 polyfuse | D24: 1 | E24: quote needed | F24: =IF(ISNUMBER(E24),D24*E24,0) -> 0 | G24: 2,500-5,000 (line) | H24: LionCircuits | I24: Bengaluru (080 phone; Karnataka facility) - address not on site, confirm | J24: Domestic | K24: 10 | M24: LCSC-type parts are not an allowed source (non-Indian); Robocraze/Probots for modules only | N24: ESTIMATE added 25 Oct. ESDS section 11 item 2: the BOM listed MAX3485ESA, XL4015 and AP2112K while the schematic uses other parts. These schematic-only parts have no vendor page opened. The range is a placeholder sized from the three superseded lines (Rs 2,712 priced) plus about 25 small parts; get a LionCircuits (or Delhi/Bengaluru distributor) quote against the generated netlist before ordering. | O24: ESTIMATE - quote needed | P24: 2026-10-25 | Q24: 2500 | R24: 5000
A25: Lane Controller PCB | B25: SUBTOTAL - Lane Controller PCB | F25: =SUM(F12:F24) -> 4476.54 | K25: =MAX(K12:K24) -> 10 | Q25: =SUM(Q12:Q24) -> 3300 | R25: =SUM(R12:R24) -> 6500
A27: UHF RFID Reader | B27: UHF integrated reader | C27: ID Tech IDT 85 mid-range UHF reader, 865-867 MHz, up to 8 m. IndustryBuying lists Wiegand + RS232 only; TradeIndia lists RS232/RS485/TCP-IP/Wiegand 26/34 and IP65. RS485, IP rating and EPC Gen2 to be confirmed in writing | D27: 1 | E27: 25959 | F27: =IF(ISNUMBER(E27),D27*E27,0) -> 25959 | H27: ID Tech Solutions Pvt Ltd (OEM); price ref. IndustryBuying | I27: Gurugram (Plot 610, Udyog Vihar Ph V; TradeIndia) | J27: Local-Delhi NCR | K27: 6 | L27: https://www.industrybuying.com/card-reader-id-tech-ITE.CAR.38552208 | M27: Eco Track Systems, New Delhi: 'RFID Integrated Reader 6 Meters' Rs 10,000 (GST n/s; interfaces not listed; the seller's page gives the UHF band as 865-928 MHz, so India-band compliance is unconfirmed) https://m.indiamart.com/ecotracksystems/integrated-reader.html | N27: Listed Rs 25,959.00 incl GST. 'Ships within 3 days' (stated). OEM's TradeIndia listing shows about Rs 14,000 (approx), so a direct quote may cut this line by about 45%. 25-Oct re-check of the IndustryBuying page: price Rs 25,959 unchanged; interfaces Wiegand + RS232 (no RS485); IP rating not listed; 9 V DC supply; -10 to 50 C operating temperature; RF output up to 30 dBm adjustable; fixed-frequency emission mode within 865-867 MHz. Ask ID Tech for: RS485 variant, WPC ETA certificate, India channel plan (865.7/866.3/866.9/867.5 MHz under G.S.R. 853(E)) and how e.r.p. is kept at or below 2 W with the built-in antenna. | O27: Product page | P27: 2026-10-25 | Q27: 0 | R27: 0
A28: UHF RFID Reader | B28: UHF test tags | C28: UHF RFID windshield tags (bench tests; the live demo uses a real FASTag) | D28: 10 | E28: 14.16 | F28: =IF(ISNUMBER(E28),D28*E28,0) -> 141.6 | H28: Eco Track Systems | I28: New Delhi (IndiaMART profile, GST 07AAFFE8904J2Z8) | J28: Local-Delhi NCR | K28: 3 | L28: https://m.indiamart.com/ecotracksystems/profile.html | N28: Listed Rs 12.00; GST not stated, +18% applied (conservative). Listed per piece on IndiaMART profile as 'RFID Windshield Tag' (UHF/EPC Gen2 not stated on the page): confirm UHF 865-867 MHz EPC Gen2 before buying. | O28: Store/category listing page | P28: 2026-10-25 | Q28: 0 | R28: 0
A29: UHF RFID Reader | B29: SUBTOTAL - UHF RFID Reader | F29: =SUM(F27:F28) -> 26100.6 | K29: =MAX(K27:K28) -> 6 | Q29: =SUM(Q27:Q28) -> 0 | R29: =SUM(R27:R28) -> 0
A31: ANPR Camera | B31: ANPR camera 2MP IR | C31: CP Plus CP-UNC-TD21ZL6C-VMDS 2MP bullet, 2.7-13.5mm motorized, 120dB WDR, 60m IR, IP67 | D31: 1 | E31: 4071 | F31: =IF(ISNUMBER(E31),D31*E31,0) -> 4071 | H31: Secure Bazaar (IndiaMART) | I31: Chennai (ships from Chennai) | J31: Domestic | K31: 7 | L31: https://m.indiamart.com/proddetail/cp-plus-cp-unc-td21zl6c-vmds-bullet-camera-2854862398948.html | M31: Deot International, New Delhi: Hikvision DS-2CD1023G0E-I 2MP IR fixed bullet Rs 3,350 excl GST (Rs 3,953) https://m.indiamart.com/proddetail/hikvision-ds-2cd1023g0e-i-2-mp-ir-fixed-network-bullet-camera-22509971212.html | N31: Listed Rs 3,450.00 excl GST; +18% GST applied. 25-Oct re-check: price Rs 3,450 excl GST unchanged, in stock, seller Secure Bazaar, Chennai. The spec table says 'Analog Camera' although the title says Network Camera. PoE, ONVIF/RTSP and the IR wavelength (850 nm required) are NOT stated; shutter is listed as 1/100000 s (implausible, treat as maximum). Get written confirmation of PoE, RTSP and 850 nm IR before payment; if 12V-only, add a PoE splitter. | O31: Product page | P31: 2026-10-25 | Q31: 0 | R31: 0
A32: ANPR Camera | B32: SUBTOTAL - ANPR Camera | F32: =SUM(F31:F31) -> 4071 | K32: =MAX(K31:K31) -> 7 | Q32: =SUM(Q31:Q31) -> 0 | R32: =SUM(R31:R31) -> 0
A34: PoE Switch | B34: PoE switch | C34: Netgear GS305P 5-port Gigabit unmanaged PoE | D34: 1 | E34: 5310 | F34: =IF(ISNUMBER(E34),D34*E34,0) -> 5310 | H34: Accruepole Pvt Ltd (IndiaMART) | I34: Mumbai (Kandivali East; ships from Mumbai) | J34: Domestic | K34: 7 | L34: https://m.indiamart.com/proddetail/5-port-gigabit-ethernet-poe-unmanaged-switch-gs305p-netgear-2856793072391.html | M34: Gigalink Technologies, Mumbai (Andheri E): Netgear 8-port, 4xPoE 53W Rs 4,200 excl GST https://m.indiamart.com/proddetail/8-port-gigabit-ethernet-plus-with-4-ports-poe-53w-24243207948.html ; PrimeABGB, Lamington Rd Mumbai: Cadyce CA-PS800 Rs 4,118 | N34: Listed Rs 4,500.00 excl GST; +18% GST applied. PoE budget and input voltage not on listing (the box includes its own DC adapter, so this switch runs from mains through its adapter, not from the 12 V rail): confirm budget >= camera + spare. The alt listing's model name is inconsistent (GS308PP vs GS108PE). | O34: Product page | P34: 2026-10-25 | Q34: 0 | R34: 0
A35: PoE Switch | B35: SUBTOTAL - PoE Switch | F35: =SUM(F34:F34) -> 5310 | K35: =MAX(K34:K34) -> 7 | Q35: =SUM(Q34:Q34) -> 0 | R35: =SUM(R34:R34) -> 0
A37: Occupancy Nodes x4 | B37: Node MCU | C37: ESP32-C3 SuperMini (RISC-V, USB-C) | D37: 4 | E37: 242 | F37: =IF(ISNUMBER(E37),D37*E37,0) -> 968 | H37: Probots (Probots Technologies) | I37: Bengaluru (Nagarbhavi; contact page) | J37: Domestic | K37: 4 | L37: https://probots.co.in/esp32-c3-supermini-wifi-bluetooth-development-board-32-bit-risc-v-uart-i2c-spi.html | M37: Probots ESP32-C3-Mini-1 dual USB-C board Rs 999 | N37: Listed Rs 242.00 incl GST. Page shows in stock, but metadata says OOS: confirm. | O37: Product page | P37: 2026-10-25 | Q37: 0 | R37: 0
A38: Occupancy Nodes x4 | B38: Distance sensor | C38: VL53L1X ToF laser ranging module (up to 4 m) | D38: 4 | E38: 799 | F38: =IF(ISNUMBER(E38),D38*E38,0) -> 3196 | H38: Probots (Probots Technologies) | I38: Bengaluru (Nagarbhavi; contact page) | J38: Domestic | K38: 14 | L38: https://probots.co.in/vl53l1x-tof-laser-ranging-sensor-module.html | M38: Thingbits, Mumbai: DFRobot A02YYUW waterproof ultrasonic Rs 1,698.02 incl GST (SOLD OUT) https://thingbits.in/products/a02yyuw-waterproof-ultrasonic-sensor | N38: Listed Rs 799.00 incl GST. OUT OF STOCK 24-Oct: 14-day lead time is an assumption. Two other Probots VL53L1X listings exist (unpriced). | O38: Product page | P38: 2026-10-25 | Q38: 0 | R38: 0
A39: Occupancy Nodes x4 | B39: Bay LED | C39: WS2812 12-LED ring | D39: 4 | E39: 149 | F39: =IF(ISNUMBER(E39),D39*E39,0) -> 596 | H39: Probots (Probots Technologies) | I39: Bengaluru (Nagarbhavi; contact page) | J39: Domestic | K39: 4 | L39: https://probots.co.in/rgb-led-12-bit-ws2812-circular-development-board.html | N39: Listed Rs 149.00 incl GST. In stock. | O39: Product page | P39: 2026-10-24 | Q39: 0 | R39: 0
A40: Occupancy Nodes x4 | B40: Node 5V supply | C40: 5V 2A USB adapter + cable per node | D40: 4 | E40: quote needed | F40: =IF(ISNUMBER(E40),D40*E40,0) -> 0 | G40: 800-1,400 (line) | H40: Local market (Delhi NCR) | I40: Delhi NCR | J40: Local-Delhi NCR | K40: 3 | N40: Not priced: quote needed (about Rs 200-350 each). | O40: ESTIMATE - quote needed | P40: 2026-10-24 | Q40: 800 | R40: 1400
A41: Occupancy Nodes x4 | B41: SUBTOTAL - Occupancy Nodes x4 | F41: =SUM(F37:F40) -> 4760 | K41: =MAX(K37:K40) -> 14 | Q41: =SUM(Q37:Q40) -> 800 | R41: =SUM(R37:R40) -> 1400
A43: P10 LED Sign | B43: P10 outdoor LED module | C43: P10 red SMD outdoor module 320x160 mm, 32x16, HUB12 | D43: 1 | E43: 699 | F43: =IF(ISNUMBER(E43),D43*E43,0) -> 699 | H43: Probots (Probots Technologies) | I43: Bengaluru (Nagarbhavi; contact page) | J43: Domestic | K43: 14 | L43: https://probots.co.in/p10-red-smd-outdoor-led-display-module-160x320mm.html | M43: Pixel Led Pvt Ltd, Navi Mumbai (Airoli): outdoor P10 red Rs 340 excl GST (Rs 401.20) https://m.indiamart.com/proddetail/outdoor-p10-red-led-display-module-21357608312.html | N43: Listed Rs 699.00 incl GST. OUT OF STOCK 24-Oct, so the alt vendor (1-week delivery stated) is the likely buy. | O43: Product page | P43: 2026-10-25 | Q43: 0 | R43: 0
A44: P10 LED Sign | B44: P10 controller (fallback) | C44: Huidu HD-W00 single-colour Wi-Fi LED controller | D44: 1 | E44: 538 | F44: =IF(ISNUMBER(E44),D44*E44,0) -> 538 | H44: Probots (Probots Technologies) | I44: Bengaluru (Nagarbhavi; contact page) | J44: Domestic | K44: 14 | L44: https://probots.co.in/w00-led-display-single-colour-wifi-controller-card-hd.html | M44: Quote: Nehru Place LED dealers | N44: Listed Rs 538.00 incl GST. OUT OF STOCK. The primary drive is HUB12 from the Lane PCB; this card is a fallback. | O44: Product page | P44: 2026-10-24 | Q44: 0 | R44: 0
A45: P10 LED Sign | B45: P10 5V supply | C45: XL4015 24V->5V buck, 5A max | D45: 1 | E45: 299 | F45: =IF(ISNUMBER(E45),D45*E45,0) -> 299 | H45: Probots (Probots Technologies) | I45: Bengaluru (Nagarbhavi; contact page) | J45: Domestic | K45: 4 | L45: https://probots.co.in/xl4015-step-down-buck-converter-adjustable-max-output-36v-5a.html | N45: Listed Rs 299.00 incl GST. In stock. | O45: Product page | P45: 2026-10-25 | Q45: 0 | R45: 0
A46: P10 LED Sign | B46: SUBTOTAL - P10 LED Sign | F46: =SUM(F43:F45) -> 1536 | K46: =MAX(K43:K45) -> 14 | Q46: =SUM(Q43:Q45) -> 0 | R46: =SUM(R43:R45) -> 0
...

Sheet Summary
A1: Subsystem | B1: Priced lines (INR) | C1: Estimate lines low (INR) | D1: Estimate lines high (INR) | E1: Budget = priced + est. high (INR) | F1: Max lead time (days) | G1: # lines | H1: # estimate lines | I1: # unpriced GAP lines (not in budget)
A2: Edge Node | B2: =BOM!F10 -> 43020 | C2: =BOM!Q10 -> 5099 | D2: =BOM!R10 -> 5499 | E2: =B2+D2 -> 48519 | F2: =BOM!K10 -> 7 | G2: 8 | H2: 2 | I2: 0
A3: Lane Controller PCB | B3: =BOM!F25 -> 4476.54 | C3: =BOM!Q25 -> 3300 | D3: =BOM!R25 -> 6500 | E3: =B3+D3 -> 10976.54 | F3: =BOM!K25 -> 10 | G3: 13 | H3: 2 | I3: 0
A4: UHF RFID Reader | B4: =BOM!F29 -> 26100.6 | C4: =BOM!Q29 -> 0 | D4: =BOM!R29 -> 0 | E4: =B4+D4 -> 26100.6 | F4: =BOM!K29 -> 6 | G4: 2 | H4: 0 | I4: 0
A5: ANPR Camera | B5: =BOM!F32 -> 4071 | C5: =BOM!Q32 -> 0 | D5: =BOM!R32 -> 0 | E5: =B5+D5 -> 4071 | F5: =BOM!K32 -> 7 | G5: 1 | H5: 0 | I5: 0
A6: PoE Switch | B6: =BOM!F35 -> 5310 | C6: =BOM!Q35 -> 0 | D6: =BOM!R35 -> 0 | E6: =B6+D6 -> 5310 | F6: =BOM!K35 -> 7 | G6: 1 | H6: 0 | I6: 0
A7: Occupancy Nodes x4 | B7: =BOM!F41 -> 4760 | C7: =BOM!Q41 -> 800 | D7: =BOM!R41 -> 1400 | E7: =B7+D7 -> 6160 | F7: =BOM!K41 -> 14 | G7: 4 | H7: 1 | I7: 0
A8: P10 LED Sign | B8: =BOM!F46 -> 1536 | C8: =BOM!Q46 -> 0 | D8: =BOM!R46 -> 0 | E8: =B8+D8 -> 1536 | F8: =BOM!K46 -> 14 | G8: 3 | H8: 0 | I8: 0
A9: Barrier Drive | B9: =BOM!F57 -> 10703.94 | C9: =BOM!Q57 -> 1700 | D9: =BOM!R57 -> 4100 | E9: =B9+D9 -> 14803.94 | F9: =BOM!K57 -> 7 | G9: 9 | H9: 2 | I9: 0
A10: Power & Protection | B10: =BOM!F72 -> 8423.32 | C10: =BOM!Q72 -> 2350 | D10: =BOM!R72 -> 4700 | E10: =B10+D10 -> 13123.32 | F10: =BOM!K72 -> 6 | G10: 13 | H10: 4 | I10: 0
A11: Mechanical | B11: =BOM!F92 -> 16431.26 | C11: =BOM!Q92 -> 10100 | D11: =BOM!R92 -> 20100 | E11: =B11+D11 -> 36531.26 | F11: =BOM!K92 -> 14 | G11: 18 | H11: 7 | I11: 0
A12: TOTAL | B12: =SUM(B2:B11) -> 124832.66 | C12: =SUM(C2:C11) -> 23349 | D12: =SUM(D2:D11) -> 42299 | E12: =SUM(E2:E11) -> 167131.66 | F12: =MAX(F2:F11) -> 14 | G12: =SUM(G2:G11) -> 72 | H12: =SUM(H2:H11) -> 18 | I12: =SUM(I2:I11) -> 0
A13: Contingency 10% | E13: =ROUND(0.1*E12,2) -> 16713.17
A14: GRAND TOTAL | E14: =E12+E13 -> 183844.83
A16: Cross-check: Summary GRAND TOTAL must equal BOM GRAND TOTAL -> | E16: =BOM!F99 -> 183844.83

Sheet Sources
A1: # | B1: URL | C1: Used for | D1: What it verified | E1: Checked on
A2: 1 | B2: https://probots.co.in/raspberry-pi-5-model-b-bcm2712-arm-cortex-a76-8gb-ram-2-4ghz-single-board-computer.html | C2: Edge Node: Raspberry Pi 5 8GB | D2: Product page | re-checked 25-Oct, see BOM notes | E2: 2026-10-25
A3: 2 | B3: https://probots.co.in/official-raspberry-pi-ai-hat-26-tops.html | C3: Edge Node: Raspberry Pi AI HAT+ 26 TOPS | D3: Product page | re-checked 25-Oct, see BOM notes | E3: 2026-10-25
A4: 3 | B4: https://probots.co.in/official-raspberry-pi-5-active-cooler-heatsink-fan.html | C4: Edge Node: Active cooler | D4: Product page | re-checked 25-Oct, see BOM notes | E4: 2026-10-25
A5: 4 | B5: https://robocraze.com/search?q=sandisk | C5: Edge Node: microSD card 128GB | D5: Store/category listing page | E5: 2026-10-24
A6: 5 | B6: https://probots.co.in/raspberry-pi-27w-usb-c-power-supply-white-in-plug.html | C6: Edge Node: USB-C PSU (bench / commissioning) | D6: Product page | re-checked 25-Oct, see BOM notes | E6: 2026-10-25
A7: 6 | B7: https://probots.co.in/xl4015-step-down-buck-converter-adjustable-max-output-36v-5a.html | C7: Edge Node: 24V->5.1V 5A buck (Pi 5 feed in enclosure) | D7: Product page | re-checked 25-Oct, see BOM notes | E7: 2026-10-25
A8: 7 | B8: https://probots.co.in/metal-case-raspberry-pi-5-x1202-ups-board.html | C8: Edge Node: Pi 5 UPS module (>=10 min ride-through) | D8: ESTIMATE - quote needed | re-checked 25-Oct, see BOM notes | E8: 2026-10-25
A9: 8 | B9: https://lioncircuits.com/parts/ESP32-S3-WROOM-1-N16R8 | C9: Lane Controller PCB: MCU module | D9: Product page | re-checked 25-Oct, see BOM notes | E9: 2026-10-25
A10: 9 | B10: https://lioncircuits.com/parts/MAX3485ESA+T | C10: Lane Controller PCB: RS485 transceiver | D10: Product page | E10: 2026-10-24
A11: 10 | B11: https://lioncircuits.com/parts/SM712.TCT | C11: Lane Controller PCB: RS485 TVS | D11: Product page | E11: 2026-10-24
A12: 11 | B12: https://probots.co.in/bts7960-43a-stepper-motor-driver-h-bridge-high-power-module-motor-control.html | C12: Lane Controller PCB: H-bridge motor driver | D12: Product page | re-checked 25-Oct, see BOM notes | E12: 2026-10-25
A13: 12 | B13: https://lioncircuits.com/parts/AP2112K-3.3TRG1 | C13: Lane Controller PCB: 3.3V regulator | D13: Product page | E13: 2026-10-24
... A90: 89 | B90: https://www.systeal.com/en/40-series-profiles/1433-aluminium-profile-10-mm-slot-80x80.html | C90: Pole mass reconciliation (non-Indian reference, not a purchase source) | D90: 80x80 10 mm slot: 4.45 kg/m, 1649 mm2, I = 130 cm4 | E90: 2026-10-25
